[2024-10-25T00:20:57.845+0000] {local_task_job_runner.py:123} INFO - ::group::Pre task execution logs
[2024-10-25T00:20:57.855+0000] {taskinstance.py:2603} INFO - Dependencies all met for dep_context=non-requeueable deps ti=<TaskInstance: paxpe_dag.run_paxpe_notebook scheduled__2024-10-20T03:00:00+00:00 [queued]>
[2024-10-25T00:20:57.859+0000] {taskinstance.py:2603} INFO - Dependencies all met for dep_context=requeueable deps ti=<TaskInstance: paxpe_dag.run_paxpe_notebook scheduled__2024-10-20T03:00:00+00:00 [queued]>
[2024-10-25T00:20:57.882+0000] {taskinstance.py:2856} INFO - Starting attempt 1 of 2
[2024-10-25T00:20:57.890+0000] {taskinstance.py:2879} INFO - Executing <Task(PapermillOperator): run_paxpe_notebook> on 2024-10-20 03:00:00+00:00
[2024-10-25T00:20:57.894+0000] {standard_task_runner.py:72} INFO - Started process 80 to run task
[2024-10-25T00:20:57.897+0000] {standard_task_runner.py:104} INFO - Running: ['***', 'tasks', 'run', 'paxpe_dag', 'run_paxpe_notebook', 'scheduled__2024-10-20T03:00:00+00:00', '--job-id', '42', '--raw', '--subdir', 'DAGS_FOLDER/paxpe_dag.py', '--cfg-path', '/tmp/tmp73s3rxnj']
[2024-10-25T00:20:57.899+0000] {standard_task_runner.py:105} INFO - Job 42: Subtask run_paxpe_notebook
[2024-10-25T00:20:57.930+0000] {task_command.py:467} INFO - Running <TaskInstance: paxpe_dag.run_paxpe_notebook scheduled__2024-10-20T03:00:00+00:00 [running]> on host 3916355df195
[2024-10-25T00:20:57.977+0000] {taskinstance.py:3122} INFO - Exporting env vars: AIRFLOW_CTX_DAG_OWNER='***' AIRFLOW_CTX_DAG_ID='paxpe_dag' AIRFLOW_CTX_TASK_ID='run_paxpe_notebook' AIRFLOW_CTX_EXECUTION_DATE='2024-10-20T03:00:00+00:00' AIRFLOW_CTX_TRY_NUMBER='1' AIRFLOW_CTX_DAG_RUN_ID='scheduled__2024-10-20T03:00:00+00:00'
[2024-10-25T00:20:57.978+0000] {taskinstance.py:731} INFO - ::endgroup::
[2024-10-25T00:20:57.988+0000] {execute.py:83} INFO - Input Notebook:  /opt/***/dags/utils/paxpe.ipynb
[2024-10-25T00:20:57.988+0000] {execute.py:84} INFO - Output Notebook: /opt/***/dags/utils/paxpe_log.ipynb
[2024-10-25T00:20:59.000+0000] {clientwrap.py:44} INFO - Executing notebook with kernel: python3
[2024-10-25T00:21:33.152+0000] {local_task_job_runner.py:341} WARNING - State of this instance has been externally set to None. Terminating instance.
[2024-10-25T00:21:33.154+0000] {local_task_job_runner.py:240} INFO - ::endgroup::
[2024-10-25T00:21:33.155+0000] {process_utils.py:132} INFO - Sending 15 to group 80. PIDs of all processes in the group: [90, 224, 567, 574, 577, 583, 593, 601, 610, 619, 623, 630, 641, 650, 658, 667, 674, 680, 689, 696, 707, 715, 722, 731, 736, 740, 858, 80]
[2024-10-25T00:21:33.155+0000] {process_utils.py:87} INFO - Sending the signal 15 to group 80
[2024-10-25T00:21:33.156+0000] {taskinstance.py:3083} ERROR - Received SIGTERM. Terminating subprocesses.
[2024-10-25T00:21:33.367+0000] {process_utils.py:80} INFO - Process psutil.Process(pid=858, status='terminated', started='00:21:22') (858) terminated with exit code None
[2024-10-25T00:21:33.368+0000] {process_utils.py:80} INFO - Process psutil.Process(pid=696, status='terminated', started='00:21:21') (696) terminated with exit code None
[2024-10-25T00:21:33.370+0000] {process_utils.py:80} INFO - Process psutil.Process(pid=641, status='terminated', started='00:21:21') (641) terminated with exit code None
[2024-10-25T00:21:33.370+0000] {process_utils.py:80} INFO - Process psutil.Process(pid=650, status='terminated', started='00:21:21') (650) terminated with exit code None
[2024-10-25T00:21:33.371+0000] {process_utils.py:80} INFO - Process psutil.Process(pid=610, status='terminated', started='00:21:21') (610) terminated with exit code None
[2024-10-25T00:21:33.372+0000] {process_utils.py:80} INFO - Process psutil.Process(pid=601, status='terminated', started='00:21:21') (601) terminated with exit code None
[2024-10-25T00:21:33.372+0000] {process_utils.py:80} INFO - Process psutil.Process(pid=736, status='terminated', started='00:21:21') (736) terminated with exit code None
[2024-10-25T00:21:33.373+0000] {process_utils.py:80} INFO - Process psutil.Process(pid=658, status='terminated', started='00:21:21') (658) terminated with exit code None
[2024-10-25T00:21:33.373+0000] {process_utils.py:80} INFO - Process psutil.Process(pid=619, status='terminated', started='00:21:21') (619) terminated with exit code None
[2024-10-25T00:21:33.426+0000] {process_utils.py:80} INFO - Process psutil.Process(pid=740, status='terminated', started='00:21:21') (740) terminated with exit code None
[2024-10-25T00:21:33.426+0000] {process_utils.py:80} INFO - Process psutil.Process(pid=567, status='terminated', started='00:21:20') (567) terminated with exit code None
[2024-10-25T00:21:33.427+0000] {process_utils.py:80} INFO - Process psutil.Process(pid=674, status='terminated', started='00:21:21') (674) terminated with exit code None
[2024-10-25T00:21:33.427+0000] {process_utils.py:80} INFO - Process psutil.Process(pid=630, status='terminated', started='00:21:21') (630) terminated with exit code None
[2024-10-25T00:21:33.427+0000] {process_utils.py:80} INFO - Process psutil.Process(pid=623, status='terminated', started='00:21:21') (623) terminated with exit code None
[2024-10-25T00:21:33.428+0000] {process_utils.py:80} INFO - Process psutil.Process(pid=577, status='terminated', started='00:21:21') (577) terminated with exit code None
[2024-10-25T00:21:33.428+0000] {process_utils.py:80} INFO - Process psutil.Process(pid=731, status='terminated', started='00:21:21') (731) terminated with exit code None
[2024-10-25T00:21:33.428+0000] {process_utils.py:80} INFO - Process psutil.Process(pid=689, status='terminated', started='00:21:21') (689) terminated with exit code None
[2024-10-25T00:21:33.428+0000] {process_utils.py:80} INFO - Process psutil.Process(pid=722, status='terminated', started='00:21:21') (722) terminated with exit code None
[2024-10-25T00:21:33.481+0000] {process_utils.py:80} INFO - Process psutil.Process(pid=680, status='terminated', started='00:21:21') (680) terminated with exit code None
[2024-10-25T00:21:33.482+0000] {process_utils.py:80} INFO - Process psutil.Process(pid=667, status='terminated', started='00:21:21') (667) terminated with exit code None
[2024-10-25T00:21:33.482+0000] {process_utils.py:80} INFO - Process psutil.Process(pid=715, status='terminated', started='00:21:21') (715) terminated with exit code None
[2024-10-25T00:21:33.482+0000] {process_utils.py:80} INFO - Process psutil.Process(pid=593, status='terminated', started='00:21:21') (593) terminated with exit code None
[2024-10-25T00:21:33.483+0000] {process_utils.py:80} INFO - Process psutil.Process(pid=583, status='terminated', started='00:21:21') (583) terminated with exit code None
[2024-10-25T00:21:33.655+0000] {process_utils.py:80} INFO - Process psutil.Process(pid=574, status='terminated', started='00:21:21') (574) terminated with exit code None
[2024-10-25T00:21:33.656+0000] {process_utils.py:80} INFO - Process psutil.Process(pid=707, status='terminated', started='00:21:21') (707) terminated with exit code None
[2024-10-25T00:21:34.292+0000] {taskinstance.py:3301} ERROR - Task failed with exception
Traceback (most recent call last):
  File "/home/airflow/.local/lib/python3.8/site-packages/airflow/models/taskinstance.py", line 767, in _execute_task
    result = _execute_callable(context=context, **execute_callable_kwargs)
  File "/home/airflow/.local/lib/python3.8/site-packages/airflow/models/taskinstance.py", line 733, in _execute_callable
    return ExecutionCallableRunner(
  File "/home/airflow/.local/lib/python3.8/site-packages/airflow/utils/operator_helpers.py", line 252, in run
    return self.func(*args, **kwargs)
  File "/home/airflow/.local/lib/python3.8/site-packages/airflow/models/baseoperator.py", line 406, in wrapper
    return func(self, *args, **kwargs)
  File "/home/airflow/.local/lib/python3.8/site-packages/airflow/providers/papermill/operators/papermill.py", line 118, in execute
    pm.execute_notebook(
  File "/home/airflow/.local/lib/python3.8/site-packages/papermill/execute.py", line 116, in execute_notebook
    nb = papermill_engines.execute_notebook_with_engine(
  File "/home/airflow/.local/lib/python3.8/site-packages/papermill/engines.py", line 48, in execute_notebook_with_engine
    return self.get_engine(engine_name).execute_notebook(nb, kernel_name, **kwargs)
  File "/home/airflow/.local/lib/python3.8/site-packages/papermill/engines.py", line 370, in execute_notebook
    cls.execute_managed_notebook(nb_man, kernel_name, log_output=log_output, **kwargs)
  File "/home/airflow/.local/lib/python3.8/site-packages/papermill/engines.py", line 442, in execute_managed_notebook
    return PapermillNotebookClient(nb_man, **final_kwargs).execute()
  File "/home/airflow/.local/lib/python3.8/site-packages/papermill/clientwrap.py", line 45, in execute
    self.papermill_execute_cells()
  File "/home/airflow/.local/lib/python3.8/site-packages/papermill/clientwrap.py", line 72, in papermill_execute_cells
    self.execute_cell(cell, index)
  File "/home/airflow/.local/lib/python3.8/site-packages/jupyter_core/utils/__init__.py", line 165, in wrapped
    return loop.run_until_complete(inner)
  File "/usr/local/lib/python3.8/asyncio/base_events.py", line 603, in run_until_complete
    self.run_forever()
  File "/usr/local/lib/python3.8/asyncio/base_events.py", line 570, in run_forever
    self._run_once()
  File "/usr/local/lib/python3.8/asyncio/base_events.py", line 1823, in _run_once
    event_list = self._selector.select(timeout)
  File "/usr/local/lib/python3.8/selectors.py", line 468, in select
    fd_event_list = self._selector.poll(timeout, max_ev)
  File "/home/airflow/.local/lib/python3.8/site-packages/airflow/models/taskinstance.py", line 3085, in signal_handler
    raise AirflowTaskTerminated("Task received SIGTERM signal")
airflow.exceptions.AirflowTaskTerminated: Task received SIGTERM signal
[2024-10-25T00:21:34.298+0000] {taskinstance.py:1225} INFO - Marking task as UP_FOR_RETRY. dag_id=paxpe_dag, task_id=run_paxpe_notebook, run_id=scheduled__2024-10-20T03:00:00+00:00, execution_date=20241020T030000, start_date=20241025T002057, end_date=20241025T002134
[2024-10-25T00:21:34.307+0000] {taskinstance.py:340} INFO - ::group::Post task execution logs
[2024-10-25T00:21:34.308+0000] {standard_task_runner.py:124} ERROR - Failed to execute job 42 for task run_paxpe_notebook ((psycopg2.errors.ForeignKeyViolation) insert or update on table "task_fail" violates foreign key constraint "task_fail_ti_fkey"
DETAIL:  Key (dag_id, task_id, run_id, map_index)=(paxpe_dag, run_paxpe_notebook, scheduled__2024-10-20T03:00:00+00:00, -1) is not present in table "task_instance".

[SQL: INSERT INTO task_fail (task_id, dag_id, run_id, map_index, start_date, end_date, duration) VALUES (%(task_id)s, %(dag_id)s, %(run_id)s, %(map_index)s, %(start_date)s, %(end_date)s, %(duration)s) RETURNING task_fail.id]
[parameters: {'task_id': 'run_paxpe_notebook', 'dag_id': 'paxpe_dag', 'run_id': 'scheduled__2024-10-20T03:00:00+00:00', 'map_index': -1, 'start_date': datetime.datetime(2024, 10, 25, 0, 20, 57, 855492, tzinfo=Timezone('UTC')), 'end_date': datetime.datetime(2024, 10, 25, 0, 21, 34, 298280, tzinfo=Timezone('UTC')), 'duration': 36}]
(Background on this error at: https://sqlalche.me/e/14/gkpj); 80)
Traceback (most recent call last):
  File "/home/airflow/.local/lib/python3.8/site-packages/airflow/models/taskinstance.py", line 273, in _run_raw_task
    TaskInstance._execute_task_with_callbacks(
  File "/home/airflow/.local/lib/python3.8/site-packages/airflow/models/taskinstance.py", line 3149, in _execute_task_with_callbacks
    result = self._execute_task(context, task_orig)
  File "/home/airflow/.local/lib/python3.8/site-packages/airflow/models/taskinstance.py", line 3173, in _execute_task
    return _execute_task(self, context, task_orig)
  File "/home/airflow/.local/lib/python3.8/site-packages/airflow/models/taskinstance.py", line 767, in _execute_task
    result = _execute_callable(context=context, **execute_callable_kwargs)
  File "/home/airflow/.local/lib/python3.8/site-packages/airflow/models/taskinstance.py", line 733, in _execute_callable
    return ExecutionCallableRunner(
  File "/home/airflow/.local/lib/python3.8/site-packages/airflow/utils/operator_helpers.py", line 252, in run
    return self.func(*args, **kwargs)
  File "/home/airflow/.local/lib/python3.8/site-packages/airflow/models/baseoperator.py", line 406, in wrapper
    return func(self, *args, **kwargs)
  File "/home/airflow/.local/lib/python3.8/site-packages/airflow/providers/papermill/operators/papermill.py", line 118, in execute
    pm.execute_notebook(
  File "/home/airflow/.local/lib/python3.8/site-packages/papermill/execute.py", line 116, in execute_notebook
    nb = papermill_engines.execute_notebook_with_engine(
  File "/home/airflow/.local/lib/python3.8/site-packages/papermill/engines.py", line 48, in execute_notebook_with_engine
    return self.get_engine(engine_name).execute_notebook(nb, kernel_name, **kwargs)
  File "/home/airflow/.local/lib/python3.8/site-packages/papermill/engines.py", line 370, in execute_notebook
    cls.execute_managed_notebook(nb_man, kernel_name, log_output=log_output, **kwargs)
  File "/home/airflow/.local/lib/python3.8/site-packages/papermill/engines.py", line 442, in execute_managed_notebook
    return PapermillNotebookClient(nb_man, **final_kwargs).execute()
  File "/home/airflow/.local/lib/python3.8/site-packages/papermill/clientwrap.py", line 45, in execute
    self.papermill_execute_cells()
  File "/home/airflow/.local/lib/python3.8/site-packages/papermill/clientwrap.py", line 72, in papermill_execute_cells
    self.execute_cell(cell, index)
  File "/home/airflow/.local/lib/python3.8/site-packages/jupyter_core/utils/__init__.py", line 165, in wrapped
    return loop.run_until_complete(inner)
  File "/usr/local/lib/python3.8/asyncio/base_events.py", line 603, in run_until_complete
    self.run_forever()
  File "/usr/local/lib/python3.8/asyncio/base_events.py", line 570, in run_forever
    self._run_once()
  File "/usr/local/lib/python3.8/asyncio/base_events.py", line 1823, in _run_once
    event_list = self._selector.select(timeout)
  File "/usr/local/lib/python3.8/selectors.py", line 468, in select
    fd_event_list = self._selector.poll(timeout, max_ev)
  File "/home/airflow/.local/lib/python3.8/site-packages/airflow/models/taskinstance.py", line 3085, in signal_handler
    raise AirflowTaskTerminated("Task received SIGTERM signal")
airflow.exceptions.AirflowTaskTerminated: Task received SIGTERM signal

During handling of the above exception, another exception occurred:

Traceback (most recent call last):
  File "/home/airflow/.local/lib/python3.8/site-packages/sqlalchemy/engine/base.py", line 1910, in _execute_context
    self.dialect.do_execute(
  File "/home/airflow/.local/lib/python3.8/site-packages/sqlalchemy/engine/default.py", line 736, in do_execute
    cursor.execute(statement, parameters)
psycopg2.errors.ForeignKeyViolation: insert or update on table "task_fail" violates foreign key constraint "task_fail_ti_fkey"
DETAIL:  Key (dag_id, task_id, run_id, map_index)=(paxpe_dag, run_paxpe_notebook, scheduled__2024-10-20T03:00:00+00:00, -1) is not present in table "task_instance".


The above exception was the direct cause of the following exception:

Traceback (most recent call last):
  File "/home/airflow/.local/lib/python3.8/site-packages/airflow/task/task_runner/standard_task_runner.py", line 117, in _start_by_fork
    ret = args.func(args, dag=self.dag)
  File "/home/airflow/.local/lib/python3.8/site-packages/airflow/cli/cli_config.py", line 49, in command
    return func(*args, **kwargs)
  File "/home/airflow/.local/lib/python3.8/site-packages/airflow/utils/cli.py", line 115, in wrapper
    return f(*args, **kwargs)
  File "/home/airflow/.local/lib/python3.8/site-packages/airflow/cli/commands/task_command.py", line 483, in task_run
    task_return_code = _run_task_by_selected_method(args, _dag, ti)
  File "/home/airflow/.local/lib/python3.8/site-packages/airflow/cli/commands/task_command.py", line 256, in _run_task_by_selected_method
    return _run_raw_task(args, ti)
  File "/home/airflow/.local/lib/python3.8/site-packages/airflow/cli/commands/task_command.py", line 341, in _run_raw_task
    return ti._run_raw_task(
  File "/home/airflow/.local/lib/python3.8/site-packages/airflow/utils/session.py", line 97, in wrapper
    return func(*args, session=session, **kwargs)
  File "/home/airflow/.local/lib/python3.8/site-packages/airflow/models/taskinstance.py", line 2995, in _run_raw_task
    return _run_raw_task(
  File "/home/airflow/.local/lib/python3.8/site-packages/airflow/models/taskinstance.py", line 327, in _run_raw_task
    ti.handle_failure(e, test_mode, context, session=session)
  File "/home/airflow/.local/lib/python3.8/site-packages/airflow/utils/session.py", line 94, in wrapper
    return func(*args, **kwargs)
  File "/home/airflow/.local/lib/python3.8/site-packages/airflow/models/taskinstance.py", line 3418, in handle_failure
    _handle_failure(
  File "/home/airflow/.local/lib/python3.8/site-packages/airflow/utils/session.py", line 94, in wrapper
    return func(*args, **kwargs)
  File "/home/airflow/.local/lib/python3.8/site-packages/airflow/api_internal/internal_api_call.py", line 139, in wrapper
    return func(*args, **kwargs)
  File "/home/airflow/.local/lib/python3.8/site-packages/airflow/models/taskinstance.py", line 1243, in _handle_failure
    TaskInstance.save_to_db(failure_context["ti"], session)
  File "/home/airflow/.local/lib/python3.8/site-packages/airflow/api_internal/internal_api_call.py", line 139, in wrapper
    return func(*args, **kwargs)
  File "/home/airflow/.local/lib/python3.8/site-packages/airflow/utils/session.py", line 94, in wrapper
    return func(*args, **kwargs)
  File "/home/airflow/.local/lib/python3.8/site-packages/airflow/models/taskinstance.py", line 3390, in save_to_db
    session.flush()
  File "/home/airflow/.local/lib/python3.8/site-packages/sqlalchemy/orm/session.py", line 3449, in flush
    self._flush(objects)
  File "/home/airflow/.local/lib/python3.8/site-packages/sqlalchemy/orm/session.py", line 3589, in _flush
    transaction.rollback(_capture_exception=True)
  File "/home/airflow/.local/lib/python3.8/site-packages/sqlalchemy/util/langhelpers.py", line 70, in __exit__
    compat.raise_(
  File "/home/airflow/.local/lib/python3.8/site-packages/sqlalchemy/util/compat.py", line 211, in raise_
    raise exception
  File "/home/airflow/.local/lib/python3.8/site-packages/sqlalchemy/orm/session.py", line 3549, in _flush
    flush_context.execute()
  File "/home/airflow/.local/lib/python3.8/site-packages/sqlalchemy/orm/unitofwork.py", line 456, in execute
    rec.execute(self)
  File "/home/airflow/.local/lib/python3.8/site-packages/sqlalchemy/orm/unitofwork.py", line 630, in execute
    util.preloaded.orm_persistence.save_obj(
  File "/home/airflow/.local/lib/python3.8/site-packages/sqlalchemy/orm/persistence.py", line 245, in save_obj
    _emit_insert_statements(
  File "/home/airflow/.local/lib/python3.8/site-packages/sqlalchemy/orm/persistence.py", line 1238, in _emit_insert_statements
    result = connection._execute_20(
  File "/home/airflow/.local/lib/python3.8/site-packages/sqlalchemy/engine/base.py", line 1710, in _execute_20
    return meth(self, args_10style, kwargs_10style, execution_options)
  File "/home/airflow/.local/lib/python3.8/site-packages/sqlalchemy/sql/elements.py", line 334, in _execute_on_connection
    return connection._execute_clauseelement(
  File "/home/airflow/.local/lib/python3.8/site-packages/sqlalchemy/engine/base.py", line 1577, in _execute_clauseelement
    ret = self._execute_context(
  File "/home/airflow/.local/lib/python3.8/site-packages/sqlalchemy/engine/base.py", line 1953, in _execute_context
    self._handle_dbapi_exception(
  File "/home/airflow/.local/lib/python3.8/site-packages/sqlalchemy/engine/base.py", line 2134, in _handle_dbapi_exception
    util.raise_(
  File "/home/airflow/.local/lib/python3.8/site-packages/sqlalchemy/util/compat.py", line 211, in raise_
    raise exception
  File "/home/airflow/.local/lib/python3.8/site-packages/sqlalchemy/engine/base.py", line 1910, in _execute_context
    self.dialect.do_execute(
  File "/home/airflow/.local/lib/python3.8/site-packages/sqlalchemy/engine/default.py", line 736, in do_execute
    cursor.execute(statement, parameters)
sqlalchemy.exc.IntegrityError: (psycopg2.errors.ForeignKeyViolation) insert or update on table "task_fail" violates foreign key constraint "task_fail_ti_fkey"
DETAIL:  Key (dag_id, task_id, run_id, map_index)=(paxpe_dag, run_paxpe_notebook, scheduled__2024-10-20T03:00:00+00:00, -1) is not present in table "task_instance".

[SQL: INSERT INTO task_fail (task_id, dag_id, run_id, map_index, start_date, end_date, duration) VALUES (%(task_id)s, %(dag_id)s, %(run_id)s, %(map_index)s, %(start_date)s, %(end_date)s, %(duration)s) RETURNING task_fail.id]
[parameters: {'task_id': 'run_paxpe_notebook', 'dag_id': 'paxpe_dag', 'run_id': 'scheduled__2024-10-20T03:00:00+00:00', 'map_index': -1, 'start_date': datetime.datetime(2024, 10, 25, 0, 20, 57, 855492, tzinfo=Timezone('UTC')), 'end_date': datetime.datetime(2024, 10, 25, 0, 21, 34, 298280, tzinfo=Timezone('UTC')), 'duration': 36}]
(Background on this error at: https://sqlalche.me/e/14/gkpj)
[2024-10-25T00:21:34.374+0000] {process_utils.py:80} INFO - Process psutil.Process(pid=90, status='terminated', started='00:20:58') (90) terminated with exit code None
[2024-10-25T00:21:34.375+0000] {process_utils.py:80} INFO - Process psutil.Process(pid=80, status='terminated', exitcode=1, started='00:20:57') (80) terminated with exit code 1
[2024-10-25T00:21:37.929+0000] {standard_task_runner.py:217} INFO - Process not found (most likely exited), stop collecting metrics
[2024-10-25T00:22:33.183+0000] {process_utils.py:150} WARNING - process psutil.Process(pid=224, name='java', status='zombie', started='00:21:12') did not respond to SIGTERM. Trying SIGKILL
[2024-10-25T00:22:33.185+0000] {process_utils.py:87} INFO - Sending the signal 9 to group 80
[2024-10-25T00:22:33.186+0000] {process_utils.py:101} INFO - Sending the signal 9 to process 80 as process group is missing.
[2024-10-25T00:23:33.199+0000] {process_utils.py:161} ERROR - Process psutil.Process(pid=224, name='java', status='zombie', started='00:21:12') (224) could not be killed. Giving up.
